Workbook
Name _2023_CF_comparison: #REF!
Name assignability_uploaded: #REF!
Name bp_uploaded: #REF!
Name Category: #REF!
Name COLA: #REF!
Name COLA_: #REF!
Name Currency_Label: #REF!
Name IQ_CH: 110000
Name IQ_CQ: 5000
Name IQ_CY: 10000
Name IQ_DAILY: 500000
Name IQ_FH: 100000
Name IQ_FQ: 500
Name IQ_FY: 1000
Name IQ_LTM: 2000
Name IQ_MONTH: 15000
Name IQ_NTM: 6000
Name IQ_WEEK: 50000
Name IQ_YTD: 3000
Name Link: #REF!
Name long: #REF!
Name millions: #REF!
Name months_year: #REF!
Name SLB: #REF!
Name SLIMS: #REF!
Name Status: #REF!
Name TCO: #REF!
Name Units: #REF!
Name Univ: #REF!
Name vdr: #REF!

Sheet data 
B1: =SUBTOTAL(3,B4:B943) -> 12 | C1: =SUBTOTAL(3,C4:C943) -> 12 | D1: =SUBTOTAL(3,D4:D943) -> 12 | E1: =SUBTOTAL(3,E4:E943) -> 12 | F1: =SUBTOTAL(3,F4:F943) -> 12 | G1: =SUBTOTAL(3,G4:G943) -> 12 | H1: =SUBTOTAL(3,H4:H943) -> 12 | I1: =SUBTOTAL(3,I4:I943) -> 12 | ... BH1: =SUBTOTAL(3,BH4:BH943) -> 12
R2: PMO | S2: PMO | T2: PMO | V2: from TCO tracker as of Jan.8,2026 | AG2: Tempo | AR2: D | AT2: Permanent
B3: FTAP SITE ID | C3: MNO Site ID | D3: Search Ring | E3: POC | F3: COOP ABBR. | G3: Project | H3: Territory | I3: Island Group | J3: Region | K3: Province | L3: Municipality | M3: Address | N3: Lat | O3: Long | P3: PMO Milestone | Q3: CME Milestone | R3: GRID Category | S3: Project Status | T3: CME Milestone | U3: Approved TSSR | V3: PMO Milestone | W3: Approved TSSR update | X3: BP secured | Y3: BP secured date | Z3: Construction Started | AA3: Construction Completed | AB3: Post Con Secured | AC3: Post Con on ST | AD3: Tap to lessor | AE3: Grid Vendor | AF3: Vendor Allocated Date | AG3: Tempo PQ Raised | AH3: PQ Number | AI3: Tempo PO Issued | AJ3: PO Number | AK3: COOP Surveyed | AL3: Tempo Permit Released | AM3: Tempo Energized | AN3: Cancelled Tempo | AO3: Advance Build | AP3: Milestone | AQ3: Aging Days | AR3: Issues | AS3: Remarks | AT3: Permanent BoQ Submitted | AU3: Permanent BoQ approved | AV3: Permanent PQ Raised | AW3: PQ Number | AX3: Permanent PO Issued | AY3: PO Number | AZ3: Line Construction Started | BA3: Line Construction Completed | BB3: Bill deposit Paid | BC3: Permanent Energized | BD3: Milestone | BE3: Aging Days | BF3: Remarks | BH3: Delay Issues
B4: PH140222 | C4: CO-A-BM-37 | D4: BrgyBialong_ShariffAguak_Maguindanao | E4: Marlone | F4: MAGELCO | G4: BTS 8 | H4: T7 | I4: MIN | J4: Autonomous Region In Muslim Mindanao (ARMM) | K4: Maguindanao | L4: Shariff Aguak (Capital) | M4: 0 | N4: 0 | O4: 0 | P4: z.1 Returned site | Q4: L - Under pre-construction | R4: =IF(INDEX(#REF!,MATCH('data '!$B4,#REF!,0),MATCH('data '!R$3,#REF!,0))=0,"",INDEX(#REF!,MATCH('data '!$B4,#REF!,0),MATCH('data '!R$3,#REF!,0))) -> #REF! | S4: =IF(INDEX(#REF!,MATCH('data '!$B4,#REF!,0),MATCH('data '!S$3,#REF!,0))=0,"",INDEX(#REF!,MATCH('data '!$B4,#REF!,0),MATCH('data '!S$3,#REF!,0))) -> #REF! | T4: =IF(INDEX(#REF!,MATCH('data '!$B4,#REF!,0),MATCH('data '!T$3,#REF!,0))=0,"",INDEX(#REF!,MATCH('data '!$B4,#REF!,0),MATCH('data '!T$3,#REF!,0))) -> #REF! | V4: z.1 Returned site | W4: 0 | AC4: =VLOOKUP(B4,#REF!,19,0) -> #REF! | AP4: =IF(AM4>0,"Tempo Energized",IF(AL4>0,"Tempo Permit Released",IF(AK4>0,"COOP Surveyed",IF(AI4>0,"PO Issued",IF(AG4>0,"PQ Raised",IF(AF4>0,"Vendor Allocated",IF(X4>0,"BP Secured","Not yet endorsed"))))))) -> Not yet endorsed | AQ4: {=IF(AM4>0,(TODAY()-AM4),IF(AL4>0,(TODAY()-AL4),IF(AK4>0,(TODAY()-AK4,IF(AI4>0,(TODAY()-AI4),IF(AG4>0,(TODAY()-AG4),IF(AF4>0,(TODAY()-AF4),IF(X4>0,(TODAY()-X4)," "))))))))} -> FALSE | BD4: =IF(BC4>0,"Permanent Energized",IF(BB4>0,"Bill deposit Paid",IF(BA4>0,"Line Construction Completed",IF(AZ4>0,"Line Construction Started",IF(AX4>0,"PO Issued",IF(AV4>0,"PQ Raised",IF(AU4>0,"BoQ Approved",IF(AT4>0,"BoQ Submitted",IF(AF4>0,"Vendor Allocated",IF(X4>0,"BP Secured",IF(U4>0,"TSSR Approved","Not yet endorsed"))))))))))) -> Not yet endorsed | BG4: #N/A
B5: PH110560 | C5: NS-BIZ18-D02 | D5: Brgy.Mandug02_DavaoCity_DavaoDelSur | E5: Marlone | F5: DASURECO | G5: BTS 8 | H5: T7 | I5: MIN | J5: Region XI (Davao Region) | K5: Davao del Sur | L5: 0 | M5: 0 | N5: 0 | O5: 0 | P5: n. Ongoing brgy permitting | Q5: L - Under pre-construction | R5: =IF(INDEX(#REF!,MATCH('data '!$B5,#REF!,0),MATCH('data '!R$3,#REF!,0))=0,"",INDEX(#REF!,MATCH('data '!$B5,#REF!,0),MATCH('data '!R$3,#REF!,0))) -> #REF! | S5: =IF(INDEX(#REF!,MATCH('data '!$B5,#REF!,0),MATCH('data '!S$3,#REF!,0))=0,"",INDEX(#REF!,MATCH('data '!$B5,#REF!,0),MATCH('data '!S$3,#REF!,0))) -> #REF! | T5: =IF(INDEX(#REF!,MATCH('data '!$B5,#REF!,0),MATCH('data '!T$3,#REF!,0))=0,"",INDEX(#REF!,MATCH('data '!$B5,#REF!,0),MATCH('data '!T$3,#REF!,0))) -> #REF! | V5: n. Ongoing brgy permitting | W5: Ongoing Brgy. Permitting | AC5: =VLOOKUP(B5,#REF!,19,0) -> #REF! | AP5: =IF(AM5>0,"Tempo Energized",IF(AL5>0,"Tempo Permit Released",IF(AK5>0,"COOP Surveyed",IF(AI5>0,"PO Issued",IF(AG5>0,"PQ Raised",IF(AF5>0,"Vendor Allocated",IF(X5>0,"BP Secured","Not yet endorsed"))))))) -> Not yet endorsed | AQ5: {=IF(AM5>0,(TODAY()-AM5),IF(AL5>0,(TODAY()-AL5),IF(AK5>0,(TODAY()-AK5,IF(AI5>0,(TODAY()-AI5),IF(AG5>0,(TODAY()-AG5),IF(AF5>0,(TODAY()-AF5),IF(X5>0,(TODAY()-X5)," "))))))))} -> FALSE | BD5: =IF(BC5>0,"Permanent Energized",IF(BB5>0,"Bill deposit Paid",IF(BA5>0,"Line Construction Completed",IF(AZ5>0,"Line Construction Started",IF(AX5>0,"PO Issued",IF(AV5>0,"PQ Raised",IF(AU5>0,"BoQ Approved",IF(AT5>0,"BoQ Submitted",IF(AF5>0,"Vendor Allocated",IF(X5>0,"BP Secured",IF(U5>0,"TSSR Approved","Not yet endorsed"))))))))))) -> Not yet endorsed | BG5: #N/A
B6: PH110548 | C6: NS-BIZ18-D04 | D6: Brgy.Bucana02_DavaoCity_DavaoDelSur | E6: Marlone | F6: DASURECO | G6: BTS 8 | H6: T7 | I6: MIN | J6: Region XI (Davao Region) | K6: Davao del Sur | L6: 0 | M6: 0 | N6: 7.054097 | O6: 125.59169 | P6: t. BP secured | Q6: L - Under pre-construction | R6: =IF(INDEX(#REF!,MATCH('data '!$B6,#REF!,0),MATCH('data '!R$3,#REF!,0))=0,"",INDEX(#REF!,MATCH('data '!$B6,#REF!,0),MATCH('data '!R$3,#REF!,0))) -> #REF! | S6: =IF(INDEX(#REF!,MATCH('data '!$B6,#REF!,0),MATCH('data '!S$3,#REF!,0))=0,"",INDEX(#REF!,MATCH('data '!$B6,#REF!,0),MATCH('data '!S$3,#REF!,0))) -> #REF! | T6: =IF(INDEX(#REF!,MATCH('data '!$B6,#REF!,0),MATCH('data '!T$3,#REF!,0))=0,"",INDEX(#REF!,MATCH('data '!$B6,#REF!,0),MATCH('data '!T$3,#REF!,0))) -> #REF! | U6: Yes | V6: r. BP applied | W6: For BP release | AC6: =VLOOKUP(B6,#REF!,19,0) -> #REF! | AP6: =IF(AM6>0,"Tempo Energized",IF(AL6>0,"Tempo Permit Released",IF(AK6>0,"COOP Surveyed",IF(AI6>0,"PO Issued",IF(AG6>0,"PQ Raised",IF(AF6>0,"Vendor Allocated",IF(X6>0,"BP Secured","Not yet endorsed"))))))) -> Not yet endorsed | AQ6: {=IF(AM6>0,(TODAY()-AM6),IF(AL6>0,(TODAY()-AL6),IF(AK6>0,(TODAY()-AK6,IF(AI6>0,(TODAY()-AI6),IF(AG6>0,(TODAY()-AG6),IF(AF6>0,(TODAY()-AF6),IF(X6>0,(TODAY()-X6)," "))))))))} -> FALSE | BD6: =IF(BC6>0,"Permanent Energized",IF(BB6>0,"Bill deposit Paid",IF(BA6>0,"Line Construction Completed",IF(AZ6>0,"Line Construction Started",IF(AX6>0,"PO Issued",IF(AV6>0,"PQ Raised",IF(AU6>0,"BoQ Approved",IF(AT6>0,"BoQ Submitted",IF(AF6>0,"Vendor Allocated",IF(X6>0,"BP Secured",IF(U6>0,"TSSR Approved","Not yet endorsed"))))))))))) -> TSSR Approved | BE6: #VALUE! | BG6: #N/A
B7: PH110582 | C7: NS-BIZ18-D08 | D7: Baluarte_TDCProperty_BrgyPanacan_DavaoCity_DavaoDelSur | E7: Marlone | F7: DASURECO | G7: BTS 8 | H7: T7 | I7: MIN | J7: Region XI (Davao Region) | K7: Davao del Sur | L7: City of Davao | M7: 0 | N7: 0 | O7: 0 | P7: a.10 For Justi submission to GT | Q7: L - Under pre-construction | R7: =IF(INDEX(#REF!,MATCH('data '!$B7,#REF!,0),MATCH('data '!R$3,#REF!,0))=0,"",INDEX(#REF!,MATCH('data '!$B7,#REF!,0),MATCH('data '!R$3,#REF!,0))) -> #REF! | S7: =IF(INDEX(#REF!,MATCH('data '!$B7,#REF!,0),MATCH('data '!S$3,#REF!,0))=0,"",INDEX(#REF!,MATCH('data '!$B7,#REF!,0),MATCH('data '!S$3,#REF!,0))) -> #REF! | T7: =IF(INDEX(#REF!,MATCH('data '!$B7,#REF!,0),MATCH('data '!T$3,#REF!,0))=0,"",INDEX(#REF!,MATCH('data '!$B7,#REF!,0),MATCH('data '!T$3,#REF!,0))) -> #REF! | V7: a.3. for Final dispo | W7: 0 | AC7: =VLOOKUP(B7,#REF!,19,0) -> #REF! | AP7: =IF(AM7>0,"Tempo Energized",IF(AL7>0,"Tempo Permit Released",IF(AK7>0,"COOP Surveyed",IF(AI7>0,"PO Issued",IF(AG7>0,"PQ Raised",IF(AF7>0,"Vendor Allocated",IF(X7>0,"BP Secured","Not yet endorsed"))))))) -> Not yet endorsed | AQ7: {=IF(AM7>0,(TODAY()-AM7),IF(AL7>0,(TODAY()-AL7),IF(AK7>0,(TODAY()-AK7,IF(AI7>0,(TODAY()-AI7),IF(AG7>0,(TODAY()-AG7),IF(AF7>0,(TODAY()-AF7),IF(X7>0,(TODAY()-X7)," "))))))))} -> FALSE | BD7: =IF(BC7>0,"Permanent Energized",IF(BB7>0,"Bill deposit Paid",IF(BA7>0,"Line Construction Completed",IF(AZ7>0,"Line Construction Started",IF(AX7>0,"PO Issued",IF(AV7>0,"PQ Raised",IF(AU7>0,"BoQ Approved",IF(AT7>0,"BoQ Submitted",IF(AF7>0,"Vendor Allocated",IF(X7>0,"BP Secured",IF(U7>0,"TSSR Approved","Not yet endorsed"))))))))))) -> Not yet endorsed | BG7: #N/A
B8: PH110558 | C8: NS-BIZ18-D10 | D8: Brgy.Waan02_DavaoCity_DavaoDelSur | E8: Marlone | F8: DASURECO | G8: BTS 8 | H8: T7 | I8: MIN | J8: Region XI (Davao Region) | K8: Davao del Sur | L8: 0 | M8: 0 | N8: 0 | O8: 0 | P8: n. Ongoing brgy permitting | Q8: L - Under pre-construction | R8: =IF(INDEX(#REF!,MATCH('data '!$B8,#REF!,0),MATCH('data '!R$3,#REF!,0))=0,"",INDEX(#REF!,MATCH('data '!$B8,#REF!,0),MATCH('data '!R$3,#REF!,0))) -> #REF! | S8: =IF(INDEX(#REF!,MATCH('data '!$B8,#REF!,0),MATCH('data '!S$3,#REF!,0))=0,"",INDEX(#REF!,MATCH('data '!$B8,#REF!,0),MATCH('data '!S$3,#REF!,0))) -> #REF! | T8: =IF(INDEX(#REF!,MATCH('data '!$B8,#REF!,0),MATCH('data '!T$3,#REF!,0))=0,"",INDEX(#REF!,MATCH('data '!$B8,#REF!,0),MATCH('data '!T$3,#REF!,0))) -> #REF! | V8: n. Ongoing brgy permitting | W8: Ongoing Brgy. Permitting | AC8: =VLOOKUP(B8,#REF!,19,0) -> #REF! | AP8: =IF(AM8>0,"Tempo Energized",IF(AL8>0,"Tempo Permit Released",IF(AK8>0,"COOP Surveyed",IF(AI8>0,"PO Issued",IF(AG8>0,"PQ Raised",IF(AF8>0,"Vendor Allocated",IF(X8>0,"BP Secured","Not yet endorsed"))))))) -> Not yet endorsed | AQ8: {=IF(AM8>0,(TODAY()-AM8),IF(AL8>0,(TODAY()-AL8),IF(AK8>0,(TODAY()-AK8,IF(AI8>0,(TODAY()-AI8),IF(AG8>0,(TODAY()-AG8),IF(AF8>0,(TODAY()-AF8),IF(X8>0,(TODAY()-X8)," "))))))))} -> FALSE | BD8: =IF(BC8>0,"Permanent Energized",IF(BB8>0,"Bill deposit Paid",IF(BA8>0,"Line Construction Completed",IF(AZ8>0,"Line Construction Started",IF(AX8>0,"PO Issued",IF(AV8>0,"PQ Raised",IF(AU8>0,"BoQ Approved",IF(AT8>0,"BoQ Submitted",IF(AF8>0,"Vendor Allocated",IF(X8>0,"BP Secured",IF(U8>0,"TSSR Approved","Not yet endorsed"))))))))))) -> Not yet endorsed | BG8: #N/A
B9: PH110553 | C9: NS-BIZ18-D21 | D9: Brgy.Buhangin(Pob.)01_DavaoCity_DavaoDelSur | E9: Marlone | F9: DASURECO | G9: BTS 8 | H9: T7 | I9: MIN | J9: Region XI (Davao Region) | K9: Davao del Sur | L9: 0 | M9: 0 | N9: 0 | O9: 0 | P9: t. BP secured | Q9: L - Under pre-construction | R9: =IF(INDEX(#REF!,MATCH('data '!$B9,#REF!,0),MATCH('data '!R$3,#REF!,0))=0,"",INDEX(#REF!,MATCH('data '!$B9,#REF!,0),MATCH('data '!R$3,#REF!,0))) -> #REF! | S9: =IF(INDEX(#REF!,MATCH('data '!$B9,#REF!,0),MATCH('data '!S$3,#REF!,0))=0,"",INDEX(#REF!,MATCH('data '!$B9,#REF!,0),MATCH('data '!S$3,#REF!,0))) -> #REF! | T9: =IF(INDEX(#REF!,MATCH('data '!$B9,#REF!,0),MATCH('data '!T$3,#REF!,0))=0,"",INDEX(#REF!,MATCH('data '!$B9,#REF!,0),MATCH('data '!T$3,#REF!,0))) -> #REF! | U9: Yes | V9: p.2 LGU Applied- Advance build | W9: ADV. RTB | X9: Yes | Y9: 45932 | AC9: =VLOOKUP(B9,#REF!,19,0) -> #REF! | AP9: =IF(AM9>0,"Tempo Energized",IF(AL9>0,"Tempo Permit Released",IF(AK9>0,"COOP Surveyed",IF(AI9>0,"PO Issued",IF(AG9>0,"PQ Raised",IF(AF9>0,"Vendor Allocated",IF(X9>0,"BP Secured","Not yet endorsed"))))))) -> BP Secured | AQ9: {=IF(AM9>0,(TODAY()-AM9),IF(AL9>0,(TODAY()-AL9),IF(AK9>0,(TODAY()-AK9,IF(AI9>0,(TODAY()-AI9),IF(AG9>0,(TODAY()-AG9),IF(AF9>0,(TODAY()-AF9),IF(X9>0,(TODAY()-X9)," "))))))))} -> FALSE | BD9: =IF(BC9>0,"Permanent Energized",IF(BB9>0,"Bill deposit Paid",IF(BA9>0,"Line Construction Completed",IF(AZ9>0,"Line Construction Started",IF(AX9>0,"PO Issued",IF(AV9>0,"PQ Raised",IF(AU9>0,"BoQ Approved",IF(AT9>0,"BoQ Submitted",IF(AF9>0,"Vendor Allocated",IF(X9>0,"BP Secured",IF(U9>0,"TSSR Approved","Not yet endorsed"))))))))))) -> BP Secured | BE9: #VALUE! | BG9: #N/A
B10: PH110547 | C10: NS-BIZ18-D31 | D10: Brgy.Pampanga_DavaoCity_DavaoDelSur | E10: Marlone | F10: DASURECO | G10: BTS 8 | H10: T7 | I10: MIN | J10: Region XI (Davao Region) | K10: Davao del Sur | L10: 0 | M10: 0 | N10: 0 | O10: 0 | P10: z.1 Returned site | Q10: L - Under pre-construction | R10: =IF(INDEX(#REF!,MATCH('data '!$B10,#REF!,0),MATCH('data '!R$3,#REF!,0))=0,"",INDEX(#REF!,MATCH('data '!$B10,#REF!,0),MATCH('data '!R$3,#REF!,0))) -> #REF! | S10: =IF(INDEX(#REF!,MATCH('data '!$B10,#REF!,0),MATCH('data '!S$3,#REF!,0))=0,"",INDEX(#REF!,MATCH('data '!$B10,#REF!,0),MATCH('data '!S$3,#REF!,0))) -> #REF! | T10: =IF(INDEX(#REF!,MATCH('data '!$B10,#REF!,0),MATCH('data '!T$3,#REF!,0))=0,"",INDEX(#REF!,MATCH('data '!$B10,#REF!,0),MATCH('data '!T$3,#REF!,0))) -> #REF! | V10: z.1 Returned site | W10: 0 | AC10: =VLOOKUP(B10,#REF!,19,0) -> #REF! | AP10: =IF(AM10>0,"Tempo Energized",IF(AL10>0,"Tempo Permit Released",IF(AK10>0,"COOP Surveyed",IF(AI10>0,"PO Issued",IF(AG10>0,"PQ Raised",IF(AF10>0,"Vendor Allocated",IF(X10>0,"BP Secured","Not yet endorsed"))))))) -> Not yet endorsed | AQ10: {=IF(AM10>0,(TODAY()-AM10),IF(AL10>0,(TODAY()-AL10),IF(AK10>0,(TODAY()-AK10,IF(AI10>0,(TODAY()-AI10),IF(AG10>0,(TODAY()-AG10),IF(AF10>0,(TODAY()-AF10),IF(X10>0,(TODAY()-X10)," "))))))))} -> FALSE | BD10: =IF(BC10>0,"Permanent Energized",IF(BB10>0,"Bill deposit Paid",IF(BA10>0,"Line Construction Completed",IF(AZ10>0,"Line Construction Started",IF(AX10>0,"PO Issued",IF(AV10>0,"PQ Raised",IF(AU10>0,"BoQ Approved",IF(AT10>0,"BoQ Submitted",IF(AF10>0,"Vendor Allocated",IF(X10>0,"BP Secured",IF(U10>0,"TSSR Approved","Not yet endorsed"))))))))))) -> Not yet endorsed | BG10: #N/A
B11: PH070479 | C11: NS-BIZ18-D55 | D11: Baluarte_TempleofLeah_BrgyBusay_CebuCity_Cebu | E11: Ralph | F11: VECO | G11: BTS 8 | H11: T6 | I11: VIS | J11: Region VII (Central Visayas) | K11: Cebu | L11: City of Cebu (Capital) | M11: 0 | N11: 0 | O11: 0 | P11: a.7. Problematic sites/Potential return sites | Q11: L - Under pre-construction | R11: =IF(INDEX(#REF!,MATCH('data '!$B11,#REF!,0),MATCH('data '!R$3,#REF!,0))=0,"",INDEX(#REF!,MATCH('data '!$B11,#REF!,0),MATCH('data '!R$3,#REF!,0))) -> #REF! | S11: =IF(INDEX(#REF!,MATCH('data '!$B11,#REF!,0),MATCH('data '!S$3,#REF!,0))=0,"",INDEX(#REF!,MATCH('data '!$B11,#REF!,0),MATCH('data '!S$3,#REF!,0))) -> #REF! | T11: =IF(INDEX(#REF!,MATCH('data '!$B11,#REF!,0),MATCH('data '!T$3,#REF!,0))=0,"",INDEX(#REF!,MATCH('data '!$B11,#REF!,0),MATCH('data '!T$3,#REF!,0))) -> #REF! | V11: z.1 Returned site | W11: 0 | AC11: =VLOOKUP(B11,#REF!,19,0) -> #REF! | AP11: =IF(AM11>0,"Tempo Energized",IF(AL11>0,"Tempo Permit Released",IF(AK11>0,"COOP Surveyed",IF(AI11>0,"PO Issued",IF(AG11>0,"PQ Raised",IF(AF11>0,"Vendor Allocated",IF(X11>0,"BP Secured","Not yet endorsed"))))))) -> Not yet endorsed | AQ11: {=IF(AM11>0,(TODAY()-AM11),IF(AL11>0,(TODAY()-AL11),IF(AK11>0,(TODAY()-AK11,IF(AI11>0,(TODAY()-AI11),IF(AG11>0,(TODAY()-AG11),IF(AF11>0,(TODAY()-AF11),IF(X11>0,(TODAY()-X11)," "))))))))} -> FALSE | BD11: =IF(BC11>0,"Permanent Energized",IF(BB11>0,"Bill deposit Paid",IF(BA11>0,"Line Construction Completed",IF(AZ11>0,"Line Construction Started",IF(AX11>0,"PO Issued",IF(AV11>0,"PQ Raised",IF(AU11>0,"BoQ Approved",IF(AT11>0,"BoQ Submitted",IF(AF11>0,"Vendor Allocated",IF(X11>0,"BP Secured",IF(U11>0,"TSSR Approved","Not yet endorsed"))))))))))) -> Not yet endorsed | BG11: #N/A
B12: PH031093 | C12: NS-BIZ18-D88 | D12: BrgyBatasanBata_SanMiguel_Bulacan | E12: CJ | F12: 0 | G12: BTS 8 | H12: T2 | I12: LUZ | J12: Region III (Central Luzon) | K12: Bulacan | L12: San Miguel | M12: 0 | N12: 0 | O12: 0 | P12: c. Ongoing candidate pre-approval | Q12: 0 | R12: =IF(INDEX(#REF!,MATCH('data '!$B12,#REF!,0),MATCH('data '!R$3,#REF!,0))=0,"",INDEX(#REF!,MATCH('data '!$B12,#REF!,0),MATCH('data '!R$3,#REF!,0))) -> #REF! | S12: =IF(INDEX(#REF!,MATCH('data '!$B12,#REF!,0),MATCH('data '!S$3,#REF!,0))=0,"",INDEX(#REF!,MATCH('data '!$B12,#REF!,0),MATCH('data '!S$3,#REF!,0))) -> #REF! | T12: =IF(INDEX(#REF!,MATCH('data '!$B12,#REF!,0),MATCH('data '!T$3,#REF!,0))=0,"",INDEX(#REF!,MATCH('data '!$B12,#REF!,0),MATCH('data '!T$3,#REF!,0))) -> #REF! | V12: z.1 Returned site | W12: 0 | AC12: =VLOOKUP(B12,#REF!,19,0) -> #REF! | AP12: =IF(AM12>0,"Tempo Energized",IF(AL12>0,"Tempo Permit Released",IF(AK12>0,"COOP Surveyed",IF(AI12>0,"PO Issued",IF(AG12>0,"PQ Raised",IF(AF12>0,"Vendor Allocated",IF(X12>0,"BP Secured","Not yet endorsed"))))))) -> Not yet endorsed | AQ12: {=IF(AM12>0,(TODAY()-AM12),IF(AL12>0,(TODAY()-AL12),IF(AK12>0,(TODAY()-AK12,IF(AI12>0,(TODAY()-AI12),IF(AG12>0,(TODAY()-AG12),IF(AF12>0,(TODAY()-AF12),IF(X12>0,(TODAY()-X12)," "))))))))} -> FALSE | BD12: =IF(BC12>0,"Permanent Energized",IF(BB12>0,"Bill deposit Paid",IF(BA12>0,"Line Construction Completed",IF(AZ12>0,"Line Construction Started",IF(AX12>0,"PO Issued",IF(AV12>0,"PQ Raised",IF(AU12>0,"BoQ Approved",IF(AT12>0,"BoQ Submitted",IF(AF12>0,"Vendor Allocated",IF(X12>0,"BP Secured",IF(U12>0,"TSSR Approved","Not yet endorsed"))))))))))) -> Not yet endorsed | BG12: #N/A
B13: PH080348 | C13: NS-BIZ18-E69 | D13: Roxas_st_corner_Bonifacio_st_Catarman_NorthernSamar | E13: Ralph | F13: NORSAMELCO | G13: BTS 8 | H13: T6 | I13: VIS | J13: Region VIII (Eastern Visayas) | K13: Northern Samar | L13: Catarman (Capital) | M13: 0 | N13: 0 | O13: 0 | P13: o. with Brgy clearance | Q13: L - Under pre-construction | R13: =IF(INDEX(#REF!,MATCH('data '!$B13,#REF!,0),MATCH('data '!R$3,#REF!,0))=0,"",INDEX(#REF!,MATCH('data '!$B13,#REF!,0),MATCH('data '!R$3,#REF!,0))) -> #REF! | S13: =IF(INDEX(#REF!,MATCH('data '!$B13,#REF!,0),MATCH('data '!S$3,#REF!,0))=0,"",INDEX(#REF!,MATCH('data '!$B13,#REF!,0),MATCH('data '!S$3,#REF!,0))) -> #REF! | T13: =IF(INDEX(#REF!,MATCH('data '!$B13,#REF!,0),MATCH('data '!T$3,#REF!,0))=0,"",INDEX(#REF!,MATCH('data '!$B13,#REF!,0),MATCH('data '!T$3,#REF!,0))) -> #REF! | V13: o. with Brgy clearance | W13: For Zone Application | AC13: =VLOOKUP(B13,#REF!,19,0) -> #REF! | AP13: =IF(AM13>0,"Tempo Energized",IF(AL13>0,"Tempo Permit Released",IF(AK13>0,"COOP Surveyed",IF(AI13>0,"PO Issued",IF(AG13>0,"PQ Raised",IF(AF13>0,"Vendor Allocated",IF(X13>0,"BP Secured","Not yet endorsed"))))))) -> Not yet endorsed | AQ13: {=IF(AM13>0,(TODAY()-AM13),IF(AL13>0,(TODAY()-AL13),IF(AK13>0,(TODAY()-AK13,IF(AI13>0,(TODAY()-AI13),IF(AG13>0,(TODAY()-AG13),IF(AF13>0,(TODAY()-AF13),IF(X13>0,(TODAY()-X13)," "))))))))} -> FALSE | BD13: =IF(BC13>0,"Permanent Energized",IF(BB13>0,"Bill deposit Paid",IF(BA13>0,"Line Construction Completed",IF(AZ13>0,"Line Construction Started",IF(AX13>0,"PO Issued",IF(AV13>0,"PQ Raised",IF(AU13>0,"BoQ Approved",IF(AT13>0,"BoQ Submitted",IF(AF13>0,"Vendor Allocated",IF(X13>0,"BP Secured",IF(U13>0,"TSSR Approved","Not yet endorsed"))))))))))) -> Not yet endorsed | BG13: #N/A
B14: PH010320 | C14: NS-BIZ19-A09 | D14: BRGYLINGSAT_SANTAMARIA_ILOCOSSUR | E14: Arjay | F14: ISECO | G14: BTS 8 | H14: T1 | I14: NLZ | J14: Region I (Ilocos Region) | K14: Ilocos Sur | L14: 0 | M14: 0 | N14: 17.3774 | O14: 120.458 | P14: t. BP secured | Q14: J - Pending SKOM | R14: =IF(INDEX(#REF!,MATCH('data '!$B14,#REF!,0),MATCH('data '!R$3,#REF!,0))=0,"",INDEX(#REF!,MATCH('data '!$B14,#REF!,0),MATCH('data '!R$3,#REF!,0))) -> #REF! | S14: =IF(INDEX(#REF!,MATCH('data '!$B14,#REF!,0),MATCH('data '!S$3,#REF!,0))=0,"",INDEX(#REF!,MATCH('data '!$B14,#REF!,0),MATCH('data '!S$3,#REF!,0))) -> #REF! | T14: =IF(INDEX(#REF!,MATCH('data '!$B14,#REF!,0),MATCH('data '!T$3,#REF!,0))=0,"",INDEX(#REF!,MATCH('data '!$B14,#REF!,0),MATCH('data '!T$3,#REF!,0))) -> #REF! | U14: Yes | V14: t. BP secured | W14: RTB | X14: Yes | Y14: 45903 | AC14: =VLOOKUP(B14,#REF!,19,0) -> #REF! | AE14: BK Engineering Services | AF14: 45938 | AG14: 45939 | AH14: FTAPPQ0013009 | AI14: 45943 | AJ14: FTAPPO0012158 | AK14: 45947 | AL14: 45979 | AM14: 45987 | AP14: =IF(AM14>0,"Tempo Energized",IF(AL14>0,"Tempo Permit Released",IF(AK14>0,"COOP Surveyed",IF(AI14>0,"PO Issued",IF(AG14>0,"PQ Raised",IF(AF14>0,"Vendor Allocated",IF(X14>0,"BP Secured","Not yet endorsed"))))))) -> Tempo Energized | AQ14: {=IF(AM14>0,(TODAY()-AM14),IF(AL14>0,(TODAY()-AL14),IF(AK14>0,(TODAY()-AK14,IF(AI14>0,(TODAY()-AI14),IF(AG14>0,(TODAY()-AG14),IF(AF14>0,(TODAY()-AF14),IF(X14>0,(TODAY()-X14)," "))))))))} -> 119 | AT14: 45994 | AU14: 46048 | AV14: 46048 | AW14: FTAPPQ0014814 | BD14: =IF(BC14>0,"Permanent Energized",IF(BB14>0,"Bill deposit Paid",IF(BA14>0,"Line Construction Completed",IF(AZ14>0,"Line Construction Started",IF(AX14>0,"PO Issued",IF(AV14>0,"PQ Raised",IF(AU14>0,"BoQ Approved",IF(AT14>0,"BoQ Submitted",IF(AF14>0,"Vendor Allocated",IF(X14>0,"BP Secured",IF(U14>0,"TSSR Approved","Not yet endorsed"))))))))))) -> PQ Raised | BE14: #N/A | BG14: BK ENGINEERING | BH14: #REF!
B15: PH070386 | C15: NS-BIZ19-A37 | D15: BrgyDamolog_Sogod_Cebu | E15: Ralph | F15: #N/A | G15: BTS 7 | H15: T6 | I15: VIS | J15: #N/A | K15: #N/A | L15: #N/A | M15: #N/A | N15: #N/A | O15: #N/A | P15: #N/A | Q15: #N/A | R15: =IF(INDEX(#REF!,MATCH('data '!$B15,#REF!,0),MATCH('data '!R$3,#REF!,0))=0,"",INDEX(#REF!,MATCH('data '!$B15,#REF!,0),MATCH('data '!R$3,#REF!,0))) -> #REF! | S15: =IF(INDEX(#REF!,MATCH('data '!$B15,#REF!,0),MATCH('data '!S$3,#REF!,0))=0,"",INDEX(#REF!,MATCH('data '!$B15,#REF!,0),MATCH('data '!S$3,#REF!,0))) -> #REF! | T15: =IF(INDEX(#REF!,MATCH('data '!$B15,#REF!,0),MATCH('data '!T$3,#REF!,0))=0,"",INDEX(#REF!,MATCH('data '!$B15,#REF!,0),MATCH('data '!T$3,#REF!,0))) -> #REF! | V15: 0 | W15: RTB | X15: Yes | Y15: 45769 | AC15: =VLOOKUP(B15,#REF!,19,0) -> #REF! | AE15: Optisolv Electrical Construction Corp. | AP15: =IF(AM15>0,"Tempo Energized",IF(AL15>0,"Tempo Permit Released",IF(AK15>0,"COOP Surveyed",IF(AI15>0,"PO Issued",IF(AG15>0,"PQ Raised",IF(AF15>0,"Vendor Allocated",IF(X15>0,"BP Secured","Not yet endorsed"))))))) -> BP Secured | AQ15: {=IF(AM15>0,(TODAY()-AM15),IF(AL15>0,(TODAY()-AL15),IF(AK15>0,(TODAY()-AK15,IF(AI15>0,(TODAY()-AI15),IF(AG15>0,(TODAY()-AG15),IF(AF15>0,(TODAY()-AF15),IF(X15>0,(TODAY()-X15)," "))))))))} -> FALSE | AT15: TBC | AU15: 45867 | AV15: 45865 | AX15: 45868 | BD15: =IF(BC15>0,"Permanent Energized",IF(BB15>0,"Bill deposit Paid",IF(BA15>0,"Line Construction Completed",IF(AZ15>0,"Line Construction Started",IF(AX15>0,"PO Issued",IF(AV15>0,"PQ Raised",IF(AU15>0,"BoQ Approved",IF(AT15>0,"BoQ Submitted",IF(AF15>0,"Vendor Allocated",IF(X15>0,"BP Secured",IF(U15>0,"TSSR Approved","Not yet endorsed"))))))))))) -> PO Issued | BE15: 72 | BG15: #N/A
B16: PH080355 | C16: NS-BIZ19-A63 | D16: BrgySanIsidro_Maasin_Leyte | E16: Ralph | F16: 0 | G16: BTS 8 | H16: T6 | I16: VIS | J16: Region VIII (Eastern Visayas) | K16: Southern Leyte | L16: 0 | M16: 0 | N16: 10.155547 | O16: 124.85228 | P16: t. BP secured | Q16: 0 | R16: =IF(INDEX(#REF!,MATCH('data '!$B16,#REF!,0),MATCH('data '!R$3,#REF!,0))=0,"",INDEX(#REF!,MATCH('data '!$B16,#REF!,0),MATCH('data '!R$3,#REF!,0))) -> #REF! | S16: =IF(INDEX(#REF!,MATCH('data '!$B16,#REF!,0),MATCH('data '!S$3,#REF!,0))=0,"",INDEX(#REF!,MATCH('data '!$B16,#REF!,0),MATCH('data '!S$3,#REF!,0))) -> #REF! | T16: =IF(INDEX(#REF!,MATCH('data '!$B16,#REF!,0),MATCH('data '!T$3,#REF!,0))=0,"",INDEX(#REF!,MATCH('data '!$B16,#REF!,0),MATCH('data '!T$3,#REF!,0))) -> #REF! | V16: u. RTB | W16: RTB | X16: Yes | Y16: 45930 | AC16: =VLOOKUP(B16,#REF!,19,0) -> #REF! | AP16: =IF(AM16>0,"Tempo Energized",IF(AL16>0,"Tempo Permit Released",IF(AK16>0,"COOP Surveyed",IF(AI16>0,"PO Issued",IF(AG16>0,"PQ Raised",IF(AF16>0,"Vendor Allocated",IF(X16>0,"BP Secured","Not yet endorsed"))))))) -> BP Secured | AQ16: {=IF(AM16>0,(TODAY()-AM16),IF(AL16>0,(TODAY()-AL16),IF(AK16>0,(TODAY()-AK16,IF(AI16>0,(TODAY()-AI16),IF(AG16>0,(TODAY()-AG16),IF(AF16>0,(TODAY()-AF16),IF(X16>0,(TODAY()-X16)," "))))))))} -> FALSE | BD16: =IF(BC16>0,"Permanent Energized",IF(BB16>0,"Bill deposit Paid",IF(BA16>0,"Line Construction Completed",IF(AZ16>0,"Line Construction Started",IF(AX16>0,"PO Issued",IF(AV16>0,"PQ Raised",IF(AU16>0,"BoQ Approved",IF(AT16>0,"BoQ Submitted",IF(AF16>0,"Vendor Allocated",IF(X16>0,"BP Secured",IF(U16>0,"TSSR Approved","Not yet endorsed"))))))))))) -> BP Secured | BE16: #VALUE! | BG16: #N/A
B17: PH140242 | C17: NS-BIZ19-A99 | D17: Brgy.Nalil_Bongao(Capital)_Tawi-Tawi | E17: Marlone | F17: TAWELCO | G17: BTS 8 | H17: T8 | I17: MIN | J17: Autonomous Region In Muslim Mindanao (ARMM) | K17: Tawi-Tawi | L17: Bongao (Capital) | M17: 0 | N17: 0 | O17: 0 | P17: p. LGU Applied | Q17: L - Under pre-construction | R17: =IF(INDEX(#REF!,MATCH('data '!$B17,#REF!,0),MATCH('data '!R$3,#REF!,0))=0,"",INDEX(#REF!,MATCH('data '!$B17,#REF!,0),MATCH('data '!R$3,#REF!,0))) -> #REF! | S17: =IF(INDEX(#REF!,MATCH('data '!$B17,#REF!,0),MATCH('data '!S$3,#REF!,0))=0,"",INDEX(#REF!,MATCH('data '!$B17,#REF!,0),MATCH('data '!S$3,#REF!,0))) -> #REF! | T17: =IF(INDEX(#REF!,MATCH('data '!$B17,#REF!,0),MATCH('data '!T$3,#REF!,0))=0,"",INDEX(#REF!,MATCH('data '!$B17,#REF!,0),MATCH('data '!T$3,#REF!,0))) -> #REF! | V17: r. BP applied | W17: For BP release | AC17: =VLOOKUP(B17,#REF!,19,0) -> #REF! | AP17: =IF(AM17>0,"Tempo Energized",IF(AL17>0,"Tempo Permit Released",IF(AK17>0,"COOP Surveyed",IF(AI17>0,"PO Issued",IF(AG17>0,"PQ Raised",IF(AF17>0,"Vendor Allocated",IF(X17>0,"BP Secured","Not yet endorsed"))))))) -> Not yet endorsed | AQ17: {=IF(AM17>0,(TODAY()-AM17),IF(AL17>0,(TODAY()-AL17),IF(AK17>0,(TODAY()-AK17,IF(AI17>0,(TODAY()-AI17),IF(AG17>0,(TODAY()-AG17),IF(AF17>0,(TODAY()-AF17),IF(X17>0,(TODAY()-X17)," "))))))))} -> FALSE | BD17: =IF(BC17>0,"Permanent Energized",IF(BB17>0,"Bill deposit Paid",IF(BA17>0,"Line Construction Completed",IF(AZ17>0,"Line Construction Started",IF(AX17>0,"PO Issued",IF(AV17>0,"PQ Raised",IF(AU17>0,"BoQ Approved",IF(AT17>0,"BoQ Submitted",IF(AF17>0,"Vendor Allocated",IF(X17>0,"BP Secured",IF(U17>0,"TSSR Approved","Not yet endorsed"))))))))))) -> Not yet endorsed | BG17: #N/A
B18: PH100349 | C18: NS-BIZ19-B36 | D18: Brgy.Magting01_Mambajao(Capital)_Camiguin | E18: Marlone | F18: CAMELCO | G18: BTS 8 | H18: T8 | I18: MIN | J18: Region X (Northern Mindanao) | K18: Camiguin | L18: Mambajao (Capital) | M18: 0 | N18: 0 | O18: 0 | P18: n. Ongoing brgy permitting | Q18: L - Under pre-construction | R18: =IF(INDEX(#REF!,MATCH('data '!$B18,#REF!,0),MATCH('data '!R$3,#REF!,0))=0,"",INDEX(#REF!,MATCH('data '!$B18,#REF!,0),MATCH('data '!R$3,#REF!,0))) -> #REF! | S18: =IF(INDEX(#REF!,MATCH('data '!$B18,#REF!,0),MATCH('data '!S$3,#REF!,0))=0,"",INDEX(#REF!,MATCH('data '!$B18,#REF!,0),MATCH('data '!S$3,#REF!,0))) -> #REF! | T18: =IF(INDEX(#REF!,MATCH('data '!$B18,#REF!,0),MATCH('data '!T$3,#REF!,0))=0,"",INDEX(#REF!,MATCH('data '!$B18,#REF!,0),MATCH('data '!T$3,#REF!,0))) -> #REF! | U18: Yes | V18: p. LGU Applied | W18: For BP Application | AC18: =VLOOKUP(B18,#REF!,19,0) -> #REF! | AP18: =IF(AM18>0,"Tempo Energized",IF(AL18>0,"Tempo Permit Released",IF(AK18>0,"COOP Surveyed",IF(AI18>0,"PO Issued",IF(AG18>0,"PQ Raised",IF(AF18>0,"Vendor Allocated",IF(X18>0,"BP Secured","Not yet endorsed"))))))) -> Not yet endorsed | AQ18: {=IF(AM18>0,(TODAY()-AM18),IF(AL18>0,(TODAY()-AL18),IF(AK18>0,(TODAY()-AK18,IF(AI18>0,(TODAY()-AI18),IF(AG18>0,(TODAY()-AG18),IF(AF18>0,(TODAY()-AF18),IF(X18>0,(TODAY()-X18)," "))))))))} -> FALSE | BD18: =IF(BC18>0,"Permanent Energized",IF(BB18>0,"Bill deposit Paid",IF(BA18>0,"Line Construction Completed",IF(AZ18>0,"Line Construction Started",IF(AX18>0,"PO Issued",IF(AV18>0,"PQ Raised",IF(AU18>0,"BoQ Approved",IF(AT18>0,"BoQ Submitted",IF(AF18>0,"Vendor Allocated",IF(X18>0,"BP Secured",IF(U18>0,"TSSR Approved","Not yet endorsed"))))))))))) -> TSSR Approved | BE18: #VALUE! | BG18: #N/A
B19: PH090083 | C19: NS-BIZ19-B69 | D19: Brgy.Ayala01_ZamboangaCity_ZamboangaDelSur | E19: Marlone | F19: ZAMCELCO | G19: BTS 8 | H19: T8 | I19: MIN | J19: Region IX (Zamboanga Peninsula) | K19: Zamboanga del Sur | L19: City of Zamboanga | M19: 0 | N19: 6.992873 | O19: 121.94626 | P19: t. BP secured | Q19: A - Energized | R19: =IF(INDEX(#REF!,MATCH('data '!$B19,#REF!,0),MATCH('data '!R$3,#REF!,0))=0,"",INDEX(#REF!,MATCH('data '!$B19,#REF!,0),MATCH('data '!R$3,#REF!,0))) -> #REF! | S19: =IF(INDEX(#REF!,MATCH('data '!$B19,#REF!,0),MATCH('data '!S$3,#REF!,0))=0,"",INDEX(#REF!,MATCH('data '!$B19,#REF!,0),MATCH('data '!S$3,#REF!,0))) -> #REF! | T19: =IF(INDEX(#REF!,MATCH('data '!$B19,#REF!,0),MATCH('data '!T$3,#REF!,0))=0,"",INDEX(#REF!,MATCH('data '!$B19,#REF!,0),MATCH('data '!T$3,#REF!,0))) -> #REF! | U19: Yes | V19: x. OP Applied | W19: RTB | X19: Yes | Y19: 45856 | AA19: 45909 | AC19: =VLOOKUP(B19,#REF!,19,0) -> #REF! | AP19: =IF(AM19>0,"Tempo Energized",IF(AL19>0,"Tempo Permit Released",IF(AK19>0,"COOP Surveyed",IF(AI19>0,"PO Issued",IF(AG19>0,"PQ Raised",IF(AF19>0,"Vendor Allocated",IF(X19>0,"BP Secured","Not yet endorsed"))))))) -> BP Secured | AQ19: {=IF(AM19>0,(TODAY()-AM19),IF(AL19>0,(TODAY()-AL19),IF(AK19>0,(TODAY()-AK19,IF(AI19>0,(TODAY()-AI19),IF(AG19>0,(TODAY()-AG19),IF(AF19>0,(TODAY()-AF19),IF(X19>0,(TODAY()-X19)," "))))))))} -> FALSE | BD19: =IF(BC19>0,"Permanent Energized",IF(BB19>0,"Bill deposit Paid",IF(BA19>0,"Line Construction Completed",IF(AZ19>0,"Line Construction Started",IF(AX19>0,"PO Issued",IF(AV19>0,"PQ Raised",IF(AU19>0,"BoQ Approved",IF(AT19>0,"BoQ Submitted",IF(AF19>0,"Vendor Allocated",IF(X19>0,"BP Secured",IF(U19>0,"TSSR Approved","Not yet endorsed"))))))))))) -> BP Secured | BE19: #VALUE! | BG19: #N/A
B20: PH080356 | C20: NS-BIZ19-B99 | D20: Brgy93Bagacay_TaclobanCity_Leyte | E20: Ralph | F20: 0 | G20: BTS 8 | H20: T6 | I20: VIS | J20: Region VIII (Eastern Visayas) | K20: Leyte | L20: 0 | M20: 0 | N20: 0 | O20: 0 | P20: r. BP applied | Q20: 0 | R20: =IF(INDEX(#REF!,MATCH('data '!$B20,#REF!,0),MATCH('data '!R$3,#REF!,0))=0,"",INDEX(#REF!,MATCH('data '!$B20,#REF!,0),MATCH('data '!R$3,#REF!,0))) -> #REF! | S20: =IF(INDEX(#REF!,MATCH('data '!$B20,#REF!,0),MATCH('data '!S$3,#REF!,0))=0,"",INDEX(#REF!,MATCH('data '!$B20,#REF!,0),MATCH('data '!S$3,#REF!,0))) -> #REF! | T20: =IF(INDEX(#REF!,MATCH('data '!$B20,#REF!,0),MATCH('data '!T$3,#REF!,0))=0,"",INDEX(#REF!,MATCH('data '!$B20,#REF!,0),MATCH('data '!T$3,#REF!,0))) -> #REF! | V20: r. BP applied | W20: For BP release | AC20: =VLOOKUP(B20,#REF!,19,0) -> #REF! | AE20: Renagmec Power Corporation | AF20: 45957 | AG20: 45957 | AH20: FTAPPQ0013327 | AI20: 45964 | AJ20: FTAPPO0012433 | AP20: =IF(AM20>0,"Tempo Energized",IF(AL20>0,"Tempo Permit Released",IF(AK20>0,"COOP Surveyed",IF(AI20>0,"PO Issued",IF(AG20>0,"PQ Raised",IF(AF20>0,"Vendor Allocated",IF(X20>0,"BP Secured","Not yet endorsed"))))))) -> PO Issued | AQ20: {=IF(AM20>0,(TODAY()-AM20),IF(AL20>0,(TODAY()-AL20),IF(AK20>0,(TODAY()-AK20,IF(AI20>0,(TODAY()-AI20),IF(AG20>0,(TODAY()-AG20),IF(AF20>0,(TODAY()-AF20),IF(X20>0,(TODAY()-X20)," "))))))))} -> FALSE | BD20: =IF(BC20>0,"Permanent Energized",IF(BB20>0,"Bill deposit Paid",IF(BA20>0,"Line Construction Completed",IF(AZ20>0,"Line Construction Started",IF(AX20>0,"PO Issued",IF(AV20>0,"PQ Raised",IF(AU20>0,"BoQ Approved",IF(AT20>0,"BoQ Submitted",IF(AF20>0,"Vendor Allocated",IF(X20>0,"BP Secured",IF(U20>0,"TSSR Approved","Not yet endorsed"))))))))))) -> Vendor Allocated | BG20: #N/A
B21: PH110606 | C21: NS-BIZ19-C19 | D21: Brgy.Poblacion_Malita(Capital)_DavaoOccidental | E21: Marlone | F21: 0 | G21: BTS 8 | H21: T7 | I21: MIN | J21: Region XI (Davao Region) | K21: Davao Occidental | L21: Malita (Capital) | M21: 0 | N21: 6.41458 | O21: 125.60118 | P21: t. BP secured | Q21: D - Pending Site Development Completion | R21: =IF(INDEX(#REF!,MATCH('data '!$B21,#REF!,0),MATCH('data '!R$3,#REF!,0))=0,"",INDEX(#REF!,MATCH('data '!$B21,#REF!,0),MATCH('data '!R$3,#REF!,0))) -> #REF! | S21: =IF(INDEX(#REF!,MATCH('data '!$B21,#REF!,0),MATCH('data '!S$3,#REF!,0))=0,"",INDEX(#REF!,MATCH('data '!$B21,#REF!,0),MATCH('data '!S$3,#REF!,0))) -> #REF! | T21: =IF(INDEX(#REF!,MATCH('data '!$B21,#REF!,0),MATCH('data '!T$3,#REF!,0))=0,"",INDEX(#REF!,MATCH('data '!$B21,#REF!,0),MATCH('data '!T$3,#REF!,0))) -> #REF! | V21: x. OP Applied | W21: RTB | X21: Yes | Y21: 45869 | Z21: 45877 | AC21: =VLOOKUP(B21,#REF!,19,0) -> #REF! | AP21: =IF(AM21>0,"Tempo Energized",IF(AL21>0,"Tempo Permit Released",IF(AK21>0,"COOP Surveyed",IF(AI21>0,"PO Issued",IF(AG21>0,"PQ Raised",IF(AF21>0,"Vendor Allocated",IF(X21>0,"BP Secured","Not yet endorsed"))))))) -> BP Secured | AQ21: {=IF(AM21>0,(TODAY()-AM21),IF(AL21>0,(TODAY()-AL21),IF(AK21>0,(TODAY()-AK21,IF(AI21>0,(TODAY()-AI21),IF(AG21>0,(TODAY()-AG21),IF(AF21>0,(TODAY()-AF21),IF(X21>0,(TODAY()-X21)," "))))))))} -> FALSE | BD21: =IF(BC21>0,"Permanent Energized",IF(BB21>0,"Bill deposit Paid",IF(BA21>0,"Line Construction Completed",IF(AZ21>0,"Line Construction Started",IF(AX21>0,"PO Issued",IF(AV21>0,"PQ Raised",IF(AU21>0,"BoQ Approved",IF(AT21>0,"BoQ Submitted",IF(AF21>0,"Vendor Allocated",IF(X21>0,"BP Secured",IF(U21>0,"TSSR Approved","Not yet endorsed"))))))))))) -> BP Secured | BE21: #VALUE! | BG21: #N/A
B22: PH070521 | C22: NS-BIZ19-C56 | D22: BrgyCogon_Tagbilaran_Bohol | E22: Ralph | F22: 0 | G22: BTS 8 | H22: T6 | I22: VIS | J22: Region VII (Central Visayas) | K22: Bohol | L22: City of Tagbilaran (Capital) | M22: 0 | N22: 0 | O22: 0 | P22: h. Pending GT TSSR Approval | Q22: 0 | R22: =IF(INDEX(#REF!,MATCH('data '!$B22,#REF!,0),MATCH('data '!R$3,#REF!,0))=0,"",INDEX(#REF!,MATCH('data '!$B22,#REF!,0),MATCH('data '!R$3,#REF!,0))) -> #REF! | S22: =IF(INDEX(#REF!,MATCH('data '!$B22,#REF!,0),MATCH('data '!S$3,#REF!,0))=0,"",INDEX(#REF!,MATCH('data '!$B22,#REF!,0),MATCH('data '!S$3,#REF!,0))) -> #REF! | T22: =IF(INDEX(#REF!,MATCH('data '!$B22,#REF!,0),MATCH('data '!T$3,#REF!,0))=0,"",INDEX(#REF!,MATCH('data '!$B22,#REF!,0),MATCH('data '!T$3,#REF!,0))) -> #REF! | V22: p. LGU Applied | W22: For BP Application | AC22: =VLOOKUP(B22,#REF!,19,0) -> #REF! | AP22: =IF(AM22>0,"Tempo Energized",IF(AL22>0,"Tempo Permit Released",IF(AK22>0,"COOP Surveyed",IF(AI22>0,"PO Issued",IF(AG22>0,"PQ Raised",IF(AF22>0,"Vendor Allocated",IF(X22>0,"BP Secured","Not yet endorsed"))))))) -> Not yet endorsed | AQ22: {=IF(AM22>0,(TODAY()-AM22),IF(AL22>0,(TODAY()-AL22),IF(AK22>0,(TODAY()-AK22,IF(AI22>0,(TODAY()-AI22),IF(AG22>0,(TODAY()-AG22),IF(AF22>0,(TODAY()-AF22),IF(X22>0,(TODAY()-X22)," "))))))))} -> FALSE | BD22: =IF(BC22>0,"Permanent Energized",IF(BB22>0,"Bill deposit Paid",IF(BA22>0,"Line Construction Completed",IF(AZ22>0,"Line Construction Started",IF(AX22>0,"PO Issued",IF(AV22>0,"PQ Raised",IF(AU22>0,"BoQ Approved",IF(AT22>0,"BoQ Submitted",IF(AF22>0,"Vendor Allocated",IF(X22>0,"BP Secured",IF(U22>0,"TSSR Approved","Not yet endorsed"))))))))))) -> Not yet endorsed | BG22: #N/A
B23: PH150158 | C23: NS-BIZ19-C94 | D23: BrgyGobgob_TabukCity_Kalinga | E23: Marilyn | F23: KAELCO | G23: BTS 8 | H23: T1 | I23: NLZ | J23: Cordillera Administrative Region (CAR) | K23: Kalinga | L23: City of Tabuk (Capital) | M23: 0 | N23: 17.4737 | O23: 121.4321 | P23: c. Ongoing candidate pre-approval | Q23: L - Under pre-construction | R23: =IF(INDEX(#REF!,MATCH('data '!$B23,#REF!,0),MATCH('data '!R$3,#REF!,0))=0,"",INDEX(#REF!,MATCH('data '!$B23,#REF!,0),MATCH('data '!R$3,#REF!,0))) -> #REF! | S23: =IF(INDEX(#REF!,MATCH('data '!$B23,#REF!,0),MATCH('data '!S$3,#REF!,0))=0,"",INDEX(#REF!,MATCH('data '!$B23,#REF!,0),MATCH('data '!S$3,#REF!,0))) -> #REF! | T23: =IF(INDEX(#REF!,MATCH('data '!$B23,#REF!,0),MATCH('data '!T$3,#REF!,0))=0,"",INDEX(#REF!,MATCH('data '!$B23,#REF!,0),MATCH('data '!T$3,#REF!,0))) -> #REF! | V23: z.1 Returned site | W23: 0 | AC23: =VLOOKUP(B23,#REF!,19,0) -> #REF! | AE23: Carlson Electrical Supply and Services | AP23: =IF(AM23>0,"Tempo Energized",IF(AL23>0,"Tempo Permit Released",IF(AK23>0,"COOP Surveyed",IF(AI23>0,"PO Issued",IF(AG23>0,"PQ Raised",IF(AE23>0,"Vendor Allocated",IF(X23>0,"BP Secured","Not yet endorsed"))))))) -> Vendor Allocated | AQ23: {=IF(AM23>0,(TODAY()-AM23),IF(AL23>0,(TODAY()-AL23),IF(AK23>0,(TODAY()-AK23,IF(AI23>0,(TODAY()-AI23),IF(AG23>0,(TODAY()-AG23),IF(AE23>0,(TODAY()-AE23),IF(X23>0,(TODAY()-X23)," "))))))))} -> FALSE | BD23: =IF(BC23>0,"Permanent Energized",IF(BB23>0,"Bill deposit Paid",IF(BA23>0,"Line Construction Completed",IF(AZ23>0,"Line Construction Started",IF(AX23>0,"PO Issued",IF(AV23>0,"PQ Raised",IF(AU23>0,"BoQ Approved",IF(AT23>0,"BoQ Submitted",IF(AE23>0,"Vendor Allocated",IF(X23>0,"BP Secured",IF(U23>0,"TSSR Approved","Not yet endorsed"))))))))))) -> Vendor Allocated | BG23: #N/A | BH23: #REF!
B24: PH140219 | C24: NS-BIZ19-D61 | D24: Brgy.Lebbuh_LamitanCity(Capital)_Basilan | E24: Marlone | F24: BASELCO | G24: BTS 8 | H24: T8 | I24: MIN | J24: Autonomous Region In Muslim Mindanao (ARMM) | K24: Basilan | L24: City of Lamitan (Capital) | M24: 0 | N24: 6.5645383 | O24: 122.17411 | P24: t. BP secured | Q24: E - Pending Tower Erection Completion | R24: =IF(INDEX(#REF!,MATCH('data '!$B24,#REF!,0),MATCH('data '!R$3,#REF!,0))=0,"",INDEX(#REF!,MATCH('data '!$B24,#REF!,0),MATCH('data '!R$3,#REF!,0))) -> #REF! | S24: =IF(INDEX(#REF!,MATCH('data '!$B24,#REF!,0),MATCH('data '!S$3,#REF!,0))=0,"",INDEX(#REF!,MATCH('data '!$B24,#REF!,0),MATCH('data '!S$3,#REF!,0))) -> #REF! | T24: =IF(INDEX(#REF!,MATCH('data '!$B24,#REF!,0),MATCH('data '!T$3,#REF!,0))=0,"",INDEX(#REF!,MATCH('data '!$B24,#REF!,0),MATCH('data '!T$3,#REF!,0))) -> #REF! | V24: t. BP secured | W24: RTB | X24: Yes | Y24: 45873 | AC24: =VLOOKUP(B24,#REF!,19,0) -> #REF! | AP24: =IF(AM24>0,"Tempo Energized",IF(AL24>0,"Tempo Permit Released",IF(AK24>0,"COOP Surveyed",IF(AI24>0,"PO Issued",IF(AG24>0,"PQ Raised",IF(AF24>0,"Vendor Allocated",IF(X24>0,"BP Secured","Not yet endorsed"))))))) -> BP Secured | AQ24: {=IF(AM24>0,(TODAY()-AM24),IF(AL24>0,(TODAY()-AL24),IF(AK24>0,(TODAY()-AK24,IF(AI24>0,(TODAY()-AI24),IF(AG24>0,(TODAY()-AG24),IF(AF24>0,(TODAY()-AF24),IF(X24>0,(TODAY()-X24)," "))))))))} -> FALSE | BD24: =IF(BC24>0,"Permanent Energized",IF(BB24>0,"Bill deposit Paid",IF(BA24>0,"Line Construction Completed",IF(AZ24>0,"Line Construction Started",IF(AX24>0,"PO Issued",IF(AV24>0,"PQ Raised",IF(AU24>0,"BoQ Approved",IF(AT24>0,"BoQ Submitted",IF(AF24>0,"Vendor Allocated",IF(X24>0,"BP Secured",IF(U24>0,"TSSR Approved","Not yet endorsed"))))))))))) -> BP Secured | BE24: #VALUE! | BG24: #N/A
B25: PH020194 | C25: NS-BIZ19-E27 | D25: BrgyAguiguican_Gattaran_Cagayan | E25: Arjay | F25: CAGELCO II | G25: BTS 8 | H25: T1 | I25: NLZ | J25: Region II (Cagayan Valley) | K25: Cagayan | L25: Gattaran | M25: 0 | N25: 18.10175 | O25: 121.66306 | P25: t. BP secured | Q25: G - Pending Foundation Completion | R25: =IF(INDEX(#REF!,MATCH('data '!$B25,#REF!,0),MATCH('data '!R$3,#REF!,0))=0,"",INDEX(#REF!,MATCH('data '!$B25,#REF!,0),MATCH('data '!R$3,#REF!,0))) -> #REF! | S25: =IF(INDEX(#REF!,MATCH('data '!$B25,#REF!,0),MATCH('data '!S$3,#REF!,0))=0,"",INDEX(#REF!,MATCH('data '!$B25,#REF!,0),MATCH('data '!S$3,#REF!,0))) -> #REF! | T25: =IF(INDEX(#REF!,MATCH('data '!$B25,#REF!,0),MATCH('data '!T$3,#REF!,0))=0,"",INDEX(#REF!,MATCH('data '!$B25,#REF!,0),MATCH('data '!T$3,#REF!,0))) -> #REF! | U25: Yes | V25: u. RTB | W25: RTB | X25: Yes | Y25: 45842 | AC25: =VLOOKUP(B25,#REF!,19,0) -> #REF! | AE25: Bangayan Electrical Services | AF25: 45908 | AG25: 45908 | AH25: FTAPPQ0012901 | AI25: 45936 | AJ25: FTAPPO0012036 | AK25: 46010 | AL25: 45915 | AM25: 46014 | AP25: =IF(AM25>0,"Tempo Energized",IF(AL25>0,"Tempo Permit Released",IF(AK25>0,"COOP Surveyed",IF(AI25>0,"PO Issued",IF(AG25>0,"PQ Raised",IF(AF25>0,"Vendor Allocated",IF(X25>0,"BP Secured","Not yet endorsed"))))))) -> Tempo Energized | AS25: 10/6/25: Waiting for TTC energization; Transformer Testing 10/15/25 10/5/25: PQ raised, takeover from Northflash | AT25: 45931 | AU25: 45945 | AV25: 45945 | AW25: FTAPPQ0013136 | AX25: 45958 | AY25: FTAPPO0012305 | BD25: =IF(BC25>0,"Permanent Energized",IF(BB25>0,"Bill deposit Paid",IF(BA25>0,"Line Construction Completed",IF(AZ25>0,"Line Construction Started",IF(AX25>0,"PO Issued",IF(AV25>0,"PQ Raised",IF(AU25>0,"BoQ Approved",IF(AT25>0,"BoQ Submitted",IF(AF25>0,"Vendor Allocated",IF(X25>0,"BP Secured",IF(U25>0,"TSSR Approved","Not yet endorsed"))))))))))) -> PO Issued | BE25: 9 | BF25: 10/6/26: Waiting Signed Staking sheet release/ Waiver for permanent construction | BG25: #N/A | BH25: #REF!
B26: PH130150 | C26: NS-BIZ19-F71 | D26: TouristRoad_BrgyPoblacionVGenLuna_SDN | E26: Marlone | F26: SIARELCO | G26: BTS 8 | H26: T8 | I26: MIN | J26: Region XIII (Caraga) | K26: Surigao del Norte | L26: General Luna | M26: 0 | N26: 0 | O26: 0 | P26: p. LGU Applied | Q26: L - Under pre-construction | R26: =IF(INDEX(#REF!,MATCH('data '!$B26,#REF!,0),MATCH('data '!R$3,#REF!,0))=0,"",INDEX(#REF!,MATCH('data '!$B26,#REF!,0),MATCH('data '!R$3,#REF!,0))) -> #REF! | S26: =IF(INDEX(#REF!,MATCH('data '!$B26,#REF!,0),MATCH('data '!S$3,#REF!,0))=0,"",INDEX(#REF!,MATCH('data '!$B26,#REF!,0),MATCH('data '!S$3,#REF!,0))) -> #REF! | T26: =IF(INDEX(#REF!,MATCH('data '!$B26,#REF!,0),MATCH('data '!T$3,#REF!,0))=0,"",INDEX(#REF!,MATCH('data '!$B26,#REF!,0),MATCH('data '!T$3,#REF!,0))) -> #REF! | U26: Yes | V26: p. LGU Applied | W26: For BP Application | AC26: =VLOOKUP(B26,#REF!,19,0) -> #REF! | AP26: =IF(AM26>0,"Tempo Energized",IF(AL26>0,"Tempo Permit Released",IF(AK26>0,"COOP Surveyed",IF(AI26>0,"PO Issued",IF(AG26>0,"PQ Raised",IF(AF26>0,"Vendor Allocated",IF(X26>0,"BP Secured","Not yet endorsed"))))))) -> Not yet endorsed | AQ26: {=IF(AM26>0,(TODAY()-AM26),IF(AL26>0,(TODAY()-AL26),IF(AK26>0,(TODAY()-AK26,IF(AI26>0,(TODAY()-AI26),IF(AG26>0,(TODAY()-AG26),IF(AF26>0,(TODAY()-AF26),IF(X26>0,(TODAY()-X26)," "))))))))} -> FALSE | BD26: =IF(BC26>0,"Permanent Energized",IF(BB26>0,"Bill deposit Paid",IF(BA26>0,"Line Construction Completed",IF(AZ26>0,"Line Construction Started",IF(AX26>0,"PO Issued",IF(AV26>0,"PQ Raised",IF(AU26>0,"BoQ Approved",IF(AT26>0,"BoQ Submitted",IF(AF26>0,"Vendor Allocated",IF(X26>0,"BP Secured",IF(U26>0,"TSSR Approved","Not yet endorsed"))))))))))) -> TSSR Approved | BE26: #VALUE! | BG26: #N/A
B27: PH030880 | C27: NS-BIZ20-A20 | D27: MtSamatShrine_BrgyDiwa_Pilar_Bataan_LGU | E27: CJ | F27: PENELCO | G27: BTS 8 | H27: T2 | I27: NLZ | J27: Region III (Central Luzon) | K27: Bataan | L27: Pilar | M27: 0 | N27: 0 | O27: 0 | P27: e.1. Pending JTSS Actual | Q27: L - Under pre-construction | R27: =IF(INDEX(#REF!,MATCH('data '!$B27,#REF!,0),MATCH('data '!R$3,#REF!,0))=0,"",INDEX(#REF!,MATCH('data '!$B27,#REF!,0),MATCH('data '!R$3,#REF!,0))) -> #REF! | S27: =IF(INDEX(#REF!,MATCH('data '!$B27,#REF!,0),MATCH('data '!S$3,#REF!,0))=0,"",INDEX(#REF!,MATCH('data '!$B27,#REF!,0),MATCH('data '!S$3,#REF!,0))) -> #REF! | T27: =IF(INDEX(#REF!,MATCH('data '!$B27,#REF!,0),MATCH('data '!T$3,#REF!,0))=0,"",INDEX(#REF!,MATCH('data '!$B27,#REF!,0),MATCH('data '!T$3,#REF!,0))) -> #REF! | V27: a.2. Long lead time | W27: 0 | AC27: =VLOOKUP(B27,#REF!,19,0) -> #REF! | AP27: =IF(AM27>0,"Tempo Energized",IF(AL27>0,"Tempo Permit Released",IF(AK27>0,"COOP Surveyed",IF(AI27>0,"PO Issued",IF(AG27>0,"PQ Raised",IF(AF27>0,"Vendor Allocated",IF(X27>0,"BP Secured","Not yet endorsed"))))))) -> Not yet endorsed | AQ27: {=IF(AM27>0,(TODAY()-AM27),IF(AL27>0,(TODAY()-AL27),IF(AK27>0,(TODAY()-AK27,IF(AI27>0,(TODAY()-AI27),IF(AG27>0,(TODAY()-AG27),IF(AF27>0,(TODAY()-AF27),IF(X27>0,(TODAY()-X27)," "))))))))} -> FALSE | BD27: =IF(BC27>0,"Permanent Energized",IF(BB27>0,"Bill deposit Paid",IF(BA27>0,"Line Construction Completed",IF(AZ27>0,"Line Construction Started",IF(AX27>0,"PO Issued",IF(AV27>0,"PQ Raised",IF(AU27>0,"BoQ Approved",IF(AT27>0,"BoQ Submitted",IF(AF27>0,"Vendor Allocated",IF(X27>0,"BP Secured",IF(U27>0,"TSSR Approved","Not yet endorsed"))))))))))) -> Not yet endorsed | BG27: #N/A
B28: PH130011 | C28: NS-BIZ20-A96 | D28: Brgy.Cortes_Basilisa(Rizal)_DinagatIslands | E28: Marlone | F28: DIELCO | G28: BTS 8 | H28: T8 | I28: MIN | J28: Region XIII (Caraga) | K28: Dinagat Islands | L28: Basilisa | M28: 0 | N28: 10.072376 | O28: 125.53834 | P28: t. BP secured | Q28: L - Under pre-construction | R28: =IF(INDEX(#REF!,MATCH('data '!$B28,#REF!,0),MATCH('data '!R$3,#REF!,0))=0,"",INDEX(#REF!,MATCH('data '!$B28,#REF!,0),MATCH('data '!R$3,#REF!,0))) -> #REF! | S28: =IF(INDEX(#REF!,MATCH('data '!$B28,#REF!,0),MATCH('data '!S$3,#REF!,0))=0,"",INDEX(#REF!,MATCH('data '!$B28,#REF!,0),MATCH('data '!S$3,#REF!,0))) -> #REF! | T28: =IF(INDEX(#REF!,MATCH('data '!$B28,#REF!,0),MATCH('data '!T$3,#REF!,0))=0,"",INDEX(#REF!,MATCH('data '!$B28,#REF!,0),MATCH('data '!T$3,#REF!,0))) -> #REF! | V28: t. BP secured | W28: RTB | X28: Yes | Y28: 45905 | AC28: =VLOOKUP(B28,#REF!,19,0) -> #REF! | AP28: =IF(AM28>0,"Tempo Energized",IF(AL28>0,"Tempo Permit Released",IF(AK28>0,"COOP Surveyed",IF(AI28>0,"PO Issued",IF(AG28>0,"PQ Raised",IF(AF28>0,"Vendor Allocated",IF(X28>0,"BP Secured","Not yet endorsed"))))))) -> BP Secured | AQ28: {=IF(AM28>0,(TODAY()-AM28),IF(AL28>0,(TODAY()-AL28),IF(AK28>0,(TODAY()-AK28,IF(AI28>0,(TODAY()-AI28),IF(AG28>0,(TODAY()-AG28),IF(AF28>0,(TODAY()-AF28),IF(X28>0,(TODAY()-X28)," "))))))))} -> FALSE | BD28: =IF(BC28>0,"Permanent Energized",IF(BB28>0,"Bill deposit Paid",IF(BA28>0,"Line Construction Completed",IF(AZ28>0,"Line Construction Started",IF(AX28>0,"PO Issued",IF(AV28>0,"PQ Raised",IF(AU28>0,"BoQ Approved",IF(AT28>0,"BoQ Submitted",IF(AF28>0,"Vendor Allocated",IF(X28>0,"BP Secured",IF(U28>0,"TSSR Approved","Not yet endorsed"))))))))))) -> BP Secured | BE28: #VALUE! | BG28: #N/A
B29: PH070512 | C29: NS-BIZ20-B27 | D29: BrgySanta Cruz_SAN FRANCISCO_CEBU | E29: Ralph | F29: 0 | G29: BTS 8 | H29: T6 | I29: VIS | J29: Region VII (Central Visayas) | K29: Cebu | L29: 0 | M29: 0 | N29: 0 | O29: 0 | P29: n. Ongoing brgy permitting | Q29: 0 | R29: =IF(INDEX(#REF!,MATCH('data '!$B29,#REF!,0),MATCH('data '!R$3,#REF!,0))=0,"",INDEX(#REF!,MATCH('data '!$B29,#REF!,0),MATCH('data '!R$3,#REF!,0))) -> #REF! | S29: =IF(INDEX(#REF!,MATCH('data '!$B29,#REF!,0),MATCH('data '!S$3,#REF!,0))=0,"",INDEX(#REF!,MATCH('data '!$B29,#REF!,0),MATCH('data '!S$3,#REF!,0))) -> #REF! | T29: =IF(INDEX(#REF!,MATCH('data '!$B29,#REF!,0),MATCH('data '!T$3,#REF!,0))=0,"",INDEX(#REF!,MATCH('data '!$B29,#REF!,0),MATCH('data '!T$3,#REF!,0))) -> #REF! | V29: n. Ongoing brgy permitting | W29: Ongoing Brgy. Permitting | AC29: =VLOOKUP(B29,#REF!,19,0) -> #REF! | AP29: =IF(AM29>0,"Tempo Energized",IF(AL29>0,"Tempo Permit Released",IF(AK29>0,"COOP Surveyed",IF(AI29>0,"PO Issued",IF(AG29>0,"PQ Raised",IF(AF29>0,"Vendor Allocated",IF(X29>0,"BP Secured","Not yet endorsed"))))))) -> Not yet endorsed | AQ29: {=IF(AM29>0,(TODAY()-AM29),IF(AL29>0,(TODAY()-AL29),IF(AK29>0,(TODAY()-AK29,IF(AI29>0,(TODAY()-AI29),IF(AG29>0,(TODAY()-AG29),IF(AF29>0,(TODAY()-AF29),IF(X29>0,(TODAY()-X29)," "))))))))} -> FALSE | BD29: =IF(BC29>0,"Permanent Energized",IF(BB29>0,"Bill deposit Paid",IF(BA29>0,"Line Construction Completed",IF(AZ29>0,"Line Construction Started",IF(AX29>0,"PO Issued",IF(AV29>0,"PQ Raised",IF(AU29>0,"BoQ Approved",IF(AT29>0,"BoQ Submitted",IF(AF29>0,"Vendor Allocated",IF(X29>0,"BP Secured",IF(U29>0,"TSSR Approved","Not yet endorsed"))))))))))) -> Not yet endorsed | BG29: #N/A
B30: PH030865 | C30: NS-BIZ20-C97 | D30: BrgyDiome_MariaAurora_Aurora | E30: CJ | F30: AURELCO | G30: BTS 8 | H30: T1 | I30: NLZ | J30: Region III (Central Luzon) | K30: Aurora | L30: Maria Aurora | M30: 0 | N30: 15.764825 | O30: 121.47094 | P30: t. BP secured | Q30: C - Pending Post-Con Permit Approval | R30: =IF(INDEX(#REF!,MATCH('data '!$B30,#REF!,0),MATCH('data '!R$3,#REF!,0))=0,"",INDEX(#REF!,MATCH('data '!$B30,#REF!,0),MATCH('data '!R$3,#REF!,0))) -> #REF! | S30: =IF(INDEX(#REF!,MATCH('data '!$B30,#REF!,0),MATCH('data '!S$3,#REF!,0))=0,"",INDEX(#REF!,MATCH('data '!$B30,#REF!,0),MATCH('data '!S$3,#REF!,0))) -> #REF! | T30: =IF(INDEX(#REF!,MATCH('data '!$B30,#REF!,0),MATCH('data '!T$3,#REF!,0))=0,"",INDEX(#REF!,MATCH('data '!$B30,#REF!,0),MATCH('data '!T$3,#REF!,0))) -> #REF! | U30: Yes | V30: y. OP secured | W30: RTB | X30: Yes | Y30: 45807 | AA30: 20/08/2025 | AC30: =VLOOKUP(B30,#REF!,19,0) -> #REF! | AE30: Bangayan Electrical Services | AF30: 45912 | AG30: 45943 | AH30: FTAPPQ0013085 | AI30: 45945 | AJ30: FTAPPO0012250 | AK30: 45936 | AL30: 45940 | AM30: 46007 | AP30: =IF(AM30>0,"Tempo Energized",IF(AL30>0,"Tempo Permit Released",IF(AK30>0,"COOP Surveyed",IF(AI30>0,"PO Issued",IF(AG30>0,"PQ Raised",IF(AF30>0,"Vendor Allocated",IF(X30>0,"BP Secured","Not yet endorsed"))))))) -> Tempo Energized | AQ30: {=IF(AM30>0,(TODAY()-AM30),IF(AL30>0,(TODAY()-AL30),IF(AK30>0,(TODAY()-AK30,IF(AI30>0,(TODAY()-AI30),IF(AG30>0,(TODAY()-AG30),IF(AF30>0,(TODAY()-AF30),IF(X30>0,(TODAY()-X30)," "))))))))} -> 99 | AR30: Original BP, EP needed. Requested to SAQ team. | AS30: 10/20/2025: Applied TTC. JTSS done, LC done, for energization once restoration in the area is done due to typhoon. 10/12/2025: Applied TTC, for temperament solution | AT30: 45903 | AU30: 45929 | AV30: 45929 | AW30: FTAPPQ0012845 | AX30: 45933 | AY30: FTAPPO0011986 | BD30: =IF(BC30>0,"Permanent Energized",IF(BB30>0,"Bill deposit Paid",IF(BA30>0,"Line Construction Completed",IF(AZ30>0,"Line Construction Started",IF(AX30>0,"PO Issued",IF(AV30>0,"PQ Raised",IF(AU30>0,"BoQ Approved",IF(AT30>0,"BoQ Submitted",IF(AF30>0,"Vendor Allocated",IF(X30>0,"BP Secured",IF(U30>0,"TSSR Approved","Not yet endorsed"))))))))))) -> PO Issued | BE30: 7 | BF30: 10/20/2025: Postcon permits needed. For transformer testing. 10/6/2025: Waiting for NTP release for Construction | BG30: #N/A | BH30: CFEI, OP
B31: PH010343 | C31: NS-BIZ20-D02 | D31: BrgyNapu_Badoc_IlocosNorte | E31: Arjay | F31: INEC | G31: BTS 8 | H31: T1 | I31: NLZ | J31: Region I (Ilocos Region) | K31: Ilocos Norte | L31: Badoc | M31: 0 | N31: 17.94223 | O31: 120.4962 | P31: t. BP secured | Q31: C - Pending Post-Con Permit Approval | R31: =IF(INDEX(#REF!,MATCH('data '!$B31,#REF!,0),MATCH('data '!R$3,#REF!,0))=0,"",INDEX(#REF!,MATCH('data '!$B31,#REF!,0),MATCH('data '!R$3,#REF!,0))) -> #REF! | S31: =IF(INDEX(#REF!,MATCH('data '!$B31,#REF!,0),MATCH('data '!S$3,#REF!,0))=0,"",INDEX(#REF!,MATCH('data '!$B31,#REF!,0),MATCH('data '!S$3,#REF!,0))) -> #REF! | T31: =IF(INDEX(#REF!,MATCH('data '!$B31,#REF!,0),MATCH('data '!T$3,#REF!,0))=0,"",INDEX(#REF!,MATCH('data '!$B31,#REF!,0),MATCH('data '!T$3,#REF!,0))) -> #REF! | U31: Yes | V31: y. OP secured | W31: RTB | X31: Yes | Y31: 45819 | Z31: 45784 | AA31: 29/09/2025 | AC31: =VLOOKUP(B31,#REF!,19,0) -> #REF! | AE31: BK Engineering Services | AF31: 45905 | AG31: 45946 | AH31: FTAPPQ0013159 | AI31: 45950 | AJ31: FTAPPO0012292 | AP31: =IF(AM31>0,"Tempo Energized",IF(AL31>0,"Tempo Permit Released",IF(AK31>0,"COOP Surveyed",IF(AI31>0,"PO Issued",IF(AG31>0,"PQ Raised",IF(AF31>0,"Vendor Allocated",IF(X31>0,"BP Secured","Not yet endorsed"))))))) -> PO Issued | AQ31: {=IF(AM31>0,(TODAY()-AM31),IF(AL31>0,(TODAY()-AL31),IF(AK31>0,(TODAY()-AK31,IF(AI31>0,(TODAY()-AI31),IF(AG31>0,(TODAY()-AG31),IF(AF31>0,(TODAY()-AF31),IF(X31>0,(TODAY()-X31)," "))))))))} -> FALSE | AT31: 45912 | AU31: 45939 | AV31: 45939 | AW31: FTAPPQ0013022 | AX31: 45943 | AY31: FTAPPO0012152 | BD31: =IF(BC31>0,"Permanent Energized",IF(BB31>0,"Bill deposit Paid",IF(BA31>0,"Line Construction Completed",IF(AZ31>0,"Line Construction Started",IF(AX31>0,"PO Issued",IF(AV31>0,"PQ Raised",IF(AU31>0,"BoQ Approved",IF(AT31>0,"BoQ Submitted",IF(AF31>0,"Vendor Allocated",IF(X31>0,"BP Secured",IF(U31>0,"TSSR Approved","Not yet endorsed"))))))))))) -> PO Issued | BE31: 1 | BF31: 10/17/25: RoW ongoing 10/7/25: Waiting BoQ Approval | BG31: #N/A | BH31: #REF!
B32: PH010364 | C32: NS-BIZ20-D26 | D32: BrgySarmingan_Narvacan_IlocosSur | E32: Arjay | F32: ISECO | G32: BTS 8 | H32: T1 | I32: NLZ | J32: Region I (Ilocos Region) | K32: Ilocos Sur | L32: Narvacan | M32: 0 | N32: 0 | O32: 0 | P32: n. Ongoing brgy permitting | Q32: L - Under pre-construction | R32: =IF(INDEX(#REF!,MATCH('data '!$B32,#REF!,0),MATCH('data '!R$3,#REF!,0))=0,"",INDEX(#REF!,MATCH('data '!$B32,#REF!,0),MATCH('data '!R$3,#REF!,0))) -> #REF! | S32: =IF(INDEX(#REF!,MATCH('data '!$B32,#REF!,0),MATCH('data '!S$3,#REF!,0))=0,"",INDEX(#REF!,MATCH('data '!$B32,#REF!,0),MATCH('data '!S$3,#REF!,0))) -> #REF! | T32: =IF(INDEX(#REF!,MATCH('data '!$B32,#REF!,0),MATCH('data '!T$3,#REF!,0))=0,"",INDEX(#REF!,MATCH('data '!$B32,#REF!,0),MATCH('data '!T$3,#REF!,0))) -> #REF! | U32: Yes | V32: o. with Brgy clearance | W32: For Zone Application | AC32: =VLOOKUP(B32,#REF!,19,0) -> #REF! | AE32: BK Engineering Services | AF32: 45938 | AP32: =IF(AM32>0,"Tempo Energized",IF(AL32>0,"Tempo Permit Released",IF(AK32>0,"COOP Surveyed",IF(AI32>0,"PO Issued",IF(AG32>0,"PQ Raised",IF(AF32>0,"Vendor Allocated",IF(X32>0,"BP Secured","Not yet endorsed"))))))) -> Vendor Allocated | AQ32: {=IF(AM32>0,(TODAY()-AM32),IF(AL32>0,(TODAY()-AL32),IF(AK32>0,(TODAY()-AK32,IF(AI32>0,(TODAY()-AI32),IF(AG32>0,(TODAY()-AG32),IF(AF32>0,(TODAY()-AF32),IF(X32>0,(TODAY()-X32)," "))))))))} -> FALSE | BD32: =IF(BC32>0,"Permanent Energized",IF(BB32>0,"Bill deposit Paid",IF(BA32>0,"Line Construction Completed",IF(AZ32>0,"Line Construction Started",IF(AX32>0,"PO Issued",IF(AV32>0,"PQ Raised",IF(AU32>0,"BoQ Approved",IF(AT32>0,"BoQ Submitted",IF(AF32>0,"Vendor Allocated",IF(X32>0,"BP Secured",IF(U32>0,"TSSR Approved","Not yet endorsed"))))))))))) -> Vendor Allocated | BE32: 2 | BG32: BK ENGINEERING | BH32: #REF!
B33: PH030789 | C33: NS-BIZ20-E55 | D33: BrgyDuale_Limay_Bataan | E33: Marilyn | F33: PENELCO | G33: BTS 7 | H33: T2 | I33: NLZ | J33: #N/A | K33: #N/A | L33: #N/A | M33: #N/A | N33: #N/A | O33: #N/A | P33: #N/A | Q33: #N/A | R33: Permanent Energized | S33: =IF(INDEX(#REF!,MATCH('data '!$B33,#REF!,0),MATCH('data '!S$3,#REF!,0))=0,"",INDEX(#REF!,MATCH('data '!$B33,#REF!,0),MATCH('data '!S$3,#REF!,0))) -> #REF! | T33: =IF(INDEX(#REF!,MATCH('data '!$B33,#REF!,0),MATCH('data '!T$3,#REF!,0))=0,"",INDEX(#REF!,MATCH('data '!$B33,#REF!,0),MATCH('data '!T$3,#REF!,0))) -> #REF! | V33: 0 | W33: RTB | X33: Yes | Y33: 45677 | AC33: =VLOOKUP(B33,#REF!,19,0) -> #REF! | AE33: Larc Telecoms, Inc. | AP33: =IF(AM33>0,"Tempo Energized",IF(AL33>0,"Tempo Permit Released",IF(AK33>0,"COOP Surveyed",IF(AI33>0,"PO Issued",IF(AG33>0,"PQ Raised",IF(AF33>0,"Vendor Allocated",IF(X33>0,"BP Secured","Not yet endorsed"))))))) -> BP Secured | AQ33: {=IF(AM33>0,(TODAY()-AM33),IF(AL33>0,(TODAY()-AL33),IF(AK33>0,(TODAY()-AK33,IF(AI33>0,(TODAY()-AI33),IF(AG33>0,(TODAY()-AG33),IF(AF33>0,(TODAY()-AF33),IF(X33>0,(TODAY()-X33)," "))))))))} -> FALSE | AS33: Permanent power energized | AT33: 45959 | AU33: 45959 | AV33: 45959 | AW33: FTAPPQ0013390 | AX33: 45964 | AY33: FTAPPO0012506 | AZ33: 45971 | BA33: 45976 | BB33: 45981 | BC33: 45988 | BD33: =IF(BC33>0,"Permanent Energized",IF(BB33>0,"Bill deposit Paid",IF(BA33>0,"Line Construction Completed",IF(AZ33>0,"Line Construction Started",IF(AX33>0,"PO Issued",IF(AV33>0,"PQ Raised",IF(AU33>0,"BoQ Approved",IF(AT33>0,"BoQ Submitted",IF(AF33>0,"Vendor Allocated",IF(X33>0,"BP Secured",IF(U33>0,"TSSR Approved","Not yet endorsed"))))))))))) -> Permanent Energized | BG33: #N/A
B34: PH100353 | C34: NS-BIZ20-F83 | D34: Brgy.ApoMacote_MalaybalayCity(Capital)_Bukidnon | E34: Marlone | F34: BUSECO | G34: BTS 8 | H34: T8 | I34: MIN | J34: Region X (Northern Mindanao) | K34: Bukidnon | L34: City of Malaybalay (Capital) | M34: Purok 6 | N34: 7.9762 | O34: 125.2084 | P34: t. BP secured | Q34: A - Energized | R34: =IF(INDEX(#REF!,MATCH('data '!$B34,#REF!,0),MATCH('data '!R$3,#REF!,0))=0,"",INDEX(#REF!,MATCH('data '!$B34,#REF!,0),MATCH('data '!R$3,#REF!,0))) -> #REF! | S34: =IF(INDEX(#REF!,MATCH('data '!$B34,#REF!,0),MATCH('data '!S$3,#REF!,0))=0,"",INDEX(#REF!,MATCH('data '!$B34,#REF!,0),MATCH('data '!S$3,#REF!,0))) -> #REF! | T34: =IF(INDEX(#REF!,MATCH('data '!$B34,#REF!,0),MATCH('data '!T$3,#REF!,0))=0,"",INDEX(#REF!,MATCH('data '!$B34,#REF!,0),MATCH('data '!T$3,#REF!,0))) -> #REF! | U34: Yes | V34: x. OP Applied | W34: RTB | X34: Yes | Y34: 45754 | AA34: 20/07/2025 | AC34: =VLOOKUP(B34,#REF!,19,0) -> #REF! | AE34: Diomon Electrical Services | AK34: 45755 | AP34: =IF(AM34>0,"Tempo Energized",IF(AL34>0,"Tempo Permit Released",IF(AK34>0,"COOP Surveyed",IF(AI34>0,"PO Issued",IF(AG34>0,"PQ Raised",IF(AF34>0,"Vendor Allocated",IF(X34>0,"BP Secured","Not yet endorsed"))))))) -> COOP Surveyed | AQ34: {=IF(AM34>0,(TODAY()-AM34),IF(AL34>0,(TODAY()-AL34),IF(AK34>0,(TODAY()-AK34,IF(AI34>0,(TODAY()-AI34),IF(AG34>0,(TODAY()-AG34),IF(AF34>0,(TODAY()-AF34),IF(X34>0,(TODAY()-X34)," "))))))))} -> #VALUE! | AT34: TBC | AU34: 45781 | AV34: 45783 | AX34: 45786 | BD34: =IF(BC34>0,"Permanent Energized",IF(BB34>0,"Bill deposit Paid",IF(BA34>0,"Line Construction Completed",IF(AZ34>0,"Line Construction Started",IF(AX34>0,"PO Issued",IF(AV34>0,"PQ Raised",IF(AU34>0,"BoQ Approved",IF(AT34>0,"BoQ Submitted",IF(AF34>0,"Vendor Allocated",IF(X34>0,"BP Secured",IF(U34>0,"TSSR Approved","Not yet endorsed"))))))))))) -> PO Issued | BE34: 154 | BG34: #N/A
B35: PH100351 | C35: NS-BIZ20-G10 | D35: Brgy.SaintPeter_MalaybalayCity(Capital)_Bukidnon | E35: Marlone | F35: BUSECO | G35: BTS 8 | H35: T8 | I35: MIN | J35: Region X (Northern Mindanao) | K35: Bukidnon | L35: City of Malaybalay (Capital) | M35: 0 | N35: 0 | O35: 0 | P35: r. BP applied | Q35: L - Under pre-construction | R35: =IF(INDEX(#REF!,MATCH('data '!$B35,#REF!,0),MATCH('data '!R$3,#REF!,0))=0,"",INDEX(#REF!,MATCH('data '!$B35,#REF!,0),MATCH('data '!R$3,#REF!,0))) -> #REF! | S35: =IF(INDEX(#REF!,MATCH('data '!$B35,#REF!,0),MATCH('data '!S$3,#REF!,0))=0,"",INDEX(#REF!,MATCH('data '!$B35,#REF!,0),MATCH('data '!S$3,#REF!,0))) -> #REF! | T35: =IF(INDEX(#REF!,MATCH('data '!$B35,#REF!,0),MATCH('data '!T$3,#REF!,0))=0,"",INDEX(#REF!,MATCH('data '!$B35,#REF!,0),MATCH('data '!T$3,#REF!,0))) -> #REF! | V35: u. RTB | W35: RTB | AC35: =VLOOKUP(B35,#REF!,19,0) -> #REF! | AP35: =IF(AM35>0,"Tempo Energized",IF(AL35>0,"Tempo Permit Released",IF(AK35>0,"COOP Surveyed",IF(AI35>0,"PO Issued",IF(AG35>0,"PQ Raised",IF(AF35>0,"Vendor Allocated",IF(X35>0,"BP Secured","Not yet endorsed"))))))) -> Not yet endorsed | AQ35: {=IF(AM35>0,(TODAY()-AM35),IF(AL35>0,(TODAY()-AL35),IF(AK35>0,(TODAY()-AK35,IF(AI35>0,(TODAY()-AI35),IF(AG35>0,(TODAY()-AG35),IF(AF35>0,(TODAY()-AF35),IF(X35>0,(TODAY()-X35)," "))))))))} -> FALSE | BD35: =IF(BC35>0,"Permanent Energized",IF(BB35>0,"Bill deposit Paid",IF(BA35>0,"Line Construction Completed",IF(AZ35>0,"Line Construction Started",IF(AX35>0,"PO Issued",IF(AV35>0,"PQ Raised",IF(AU35>0,"BoQ Approved",IF(AT35>0,"BoQ Submitted",IF(AF35>0,"Vendor Allocated",IF(X35>0,"BP Secured",IF(U35>0,"TSSR Approved","Not yet endorsed"))))))))))) -> Not yet endorsed | BG35: #N/A
